const main = async () => {
  console.log('seems to work')
}

try {
  main()
} catch (err) {
  console.error(err.message)
}